Workbook

Sheet UserSampleSubmission
B1: Sample submission | D1: version 4.14.0 | H1: All Names provided should only use the following characters : a-z, A-Z, 0-9, dash ( - ), underscore ( _ ). Do not use any other special character.
D2: (*) Mandatory fields when not greyed out
A3: Hercules Project Name | D3: *
A4: Principal Investigator | D4: *
A5: Quote number | D5: *
F6: Coordinates order | G6: Column
A8: * | B8: * | C8: * | D8: * | F8: * | G8: * | J8: * | K8: * | L8: * | M8: * | N8: * | O8: * | U8: * | V8: * | W8: * | Y8: *
A9: Sample Type | B9: Sample Kind | C9: Sample Name | D9: Pool Name | E9: Ratio Library In Pool | F9: Volume (uL) | G9: Conc. (ng/uL) | H9: Collection Site | I9: Tissue Source | J9: Container Kind | K9: Container Name | L9: Sample Coord | M9: Location Kind | N9: Location Name | O9: Container Coord | P9: Taxon | Q9: Sex | R9: Reference Genome | S9: Individual Name | T9: Cohort | U9: Library Type | V9: Platform | W9: Strandedness | X9: Index Set | Y9: Index | Z9: Selection | AA9: Selection Target | AB9: Comment

Sheet UserPoolSubmission
A1: Pool Submission | C1: Only complete this form if you are submitting pooled libraries.
C2: * | D2: *
A3: Pool Name | B3: Pool Volume | C3: Container Kind | D3: Container Name | E3: Pool Coord | F3: Comment

Sheet IndexSubmission
A1: Index Submission | C1: Only complete this form if you cannot find the index on the list provided.
A3: Index Set name :
A4: Adapter Type :
A6: Index Name | B6: Index 3 prime sequence (i7) | C6: Index 5 prime sequence (i5)

Sheet UserSampleSubmission_Example
B1: SAMPLE SUBMISSION | E1: version 4.14.0 | F1: (*) Mandatory fields
A3: Hercules Project Name | B3: Client Manifest | D3: *
A4: Principal Investigator | B4: Andres T | D4: *
A5: Quote number | B5: Q00001 | D5: *
E6: Coordinates order | F6: Column
A8: * | B8: * | C8: * | D8: * | E8: * | F8: * | I8: * | J8: * | K8: * | T8: * | U8: * | V8: * | X8: *
A9: Sample Type | B9: Sample Kind | C9: Sample Name | D9: Pool Name | E9: Volume (uL) | F9: Conc. (ng/uL) | G9: Collection Site | H9: Tissue Source | I9: Container Kind | J9: Container Name | K9: Sample Coord | L9: Location Kind | M9: Location Name | N9: Container Coord | O9: Taxon | P9: Sex | Q9: Reference Genome | R9: Individual Name | S9: Cohort | T9: Library Type | U9: Platform | V9: Strandedness | W9: Index Set | X9: Index | Y9: Selection | Z9: Selection Target | AA9: Comment
A10: Sample | B10: DNA | C10: Sample1 | E10: 55 | F10: 77 | G10: MUHC | H10: BLOOD | I10: 96-well plate | J10: PlateMUHC1 | K10: A01 | O10: Homo sapiens | P10: M | Q10: GRCh38.p14 | R10: IND_1 | S10: WE_ARE_COHORT
A11: Sample | B11: RNA | C11: Sample2 | E11: 55 | F11: 77 | G11: MUHC | H11: BLOOD | I11: 96-well plate | J11: PlateMUHC1 | K11: B01 | O11: Homo sapiens | P11: F | Q11: GRCh38.p14 | R11: IND_1 | S11: WE_ARE_COHORT
A12: Sample | B12: BAL | C12: Sample3 | E12: 55 | G12: MUHC | I12: 96-well plate | J12: PlateMUHC1 | K12: C01 | O12: Homo sapiens | P12: F | Q12: GRCh38.p14 | R12: IND_2 | S12: WE_ARE_COHORT
A13: Sample | B13: BAL | C13: Sample4 | E13: 55 | G13: MUHC | I13: 96-well plate | J13: PlateMUHC1 | K13: D01 | O13: Homo sapiens | P13: M | Q13: GRCh38.p14 | R13: IND_3 | S13: WE_ARE_COHORT
A14: Library | B14: DNA | C14: Sample5 | E14: 55 | F14: 63 | G14: Ste-Justine | H14: TISSUE | I14: 96-well plate | J14: PlateSJ1 | K14: A01 | O14: Homo sapiens | P14: F | Q14: GRCh38.p14 | R14: IND_4 | S14: WE_ARE_COHORT | T14: WGBS | U14: ILLUMINA | V14: Double stranded | W14: Agilent-SureSelect_XT_LI_low-input | X14: SSXTLI7009
A15: Sample | B15: RNA | C15: Sample6 | E15: 55 | F15: 66 | G15: Ste-Justine | H15: BUFFY COAT | I15: 96-well plate | J15: PlateSJ1 | K15: D01 | O15: Homo sapiens | P15: M | Q15: GRCh38.p14 | R15: IND_1311
A16: Sample | B16: RNA | C16: Sample7 | E16: 55 | F16: 66 | G16: Ste-Justine | H16: BUFFY COAT | I16: 96-well plate | J16: PlateSJ1 | K16: E01 | O16: Homo sapiens | P16: M | Q16: GRCh38.p14 | R16: RND_111
A17: Library | B17: DNA | C17: Sample8 | E17: 55 | F17: 66 | G17: Ste-Justine | H17: BUFFY COAT | I17: 96-well plate | J17: PlateSJ1 | K17: A02 | O17: Homo sapiens | P17: F | Q17: GRCh38.p14 | R17: IND_5 | S17: WE_ARE_COHORT | T17: PCR-free | U17: ILLUMINA | V17: Double stranded | W17: Illumina-Made_by_IDT_for_Illumina-Nextera_UDP_v3 | X17: UDP70001-UDP50001
A18: Library | B18: DNA | C18: Sample9 | E18: 55 | F18: 66 | G18: Ste-Justine | H18: BUFFY COAT | I18: 96-well plate | J18: PlateSJ1 | K18: C02 | O18: Homo sapiens | P18: Unknown | Q18: GRCh38.p14 | R18: IND_6 | S18: WE_ARE_COHORT | T18: PCR-free | U18: ILLUMINA | V18: Double stranded | W18: Illumina-Made_by_IDT_for_Illumina-Nextera_UDP_v3 | X18: UDP70002-UDP50002
A19: Library | B19: DNA | C19: Sample10 | E19: 55 | F19: 66 | G19: Ste-Justine | H19: BUFFY COAT | I19: Tube | J19: TubeErnesto | L19: Tube box 9x9 | M19: TubeBox1 | N19: A01 | O19: Homo sapiens | P19: M | Q19: GRCh38.p14 | T19: PCR-free | U19: ILLUMINA | V19: Double stranded | W19: Illumina-Made_by_IDT_for_Illumina-Nextera_UDP_v3 | X19: UDP70003V3-UDP50003V3
A20: Library | B20: DNA | C20: Sample11 | E20: 55 | F20: 66 | G20: Ste-Justine | H20: BUFFY COAT | I20: Tube | J20: TubeBrenda | L20: Tube box 9x9 | M20: TubeBox1 | N20: A02 | O20: Homo sapiens | P20: F | Q20: GRCh38.p14 | T20: PCR-enriched | U20: ILLUMINA | V20: Double stranded | W20: Illumina-Made_by_IDT_for_Illumina-Nextera_UDP_v3 | X20: UDP70004-UDP50004
A21: Library | B21: DNA | C21: Sample12 | E21: 55 | F21: 66 | G21: Ste-Justine | H21: BUFFY COAT | I21: Tube | J21: TubeBrenda2 | L21: Tube rack 8x12 | M21: TubeRack1 | N21: A01 | O21: Homo sapiens | P21: Unknown | Q21: GRCh38.p14 | T21: PCR-enriched | U21: ILLUMINA | V21: Double stranded | W21: Illumina-Made_by_IDT_for_Illumina-Nextera_UDP_v3 | X21: UDP70005V3-UDP50005V3
A22: Library in pool | B22: DNA | C22: PooledLibrary1 | D22: Pool1 | E22: 55 | G22: MUHC | H22: BUFFY COAT | O22: Mus musculus | P22: M | Q22: GRCm39 | R22: MOUSE_1 | T22: RNASeq | U22: ILLUMINA | V22: Double stranded | W22: Illumina-Made_by_IDT_for_Illumina-Nextera_UDP_v3 | X22: UDP70006-UDP50006
A23: Library in pool | B23: DNA | C23: PooledLibrary2 | D23: Pool1 | E23: 55 | G23: MUHC | H23: BUFFY COAT | O23: Mus musculus | P23: F | Q23: GRCm39 | R23: MOUSE_2 | T23: RNASeq | U23: ILLUMINA | V23: Double stranded | W23: Illumina-Made_by_IDT_for_Illumina-Nextera_UDP_v3 | X23: UDP70007-UDP50007
A24: Library in pool | B24: DNA | C24: PooledLibrary3 | D24: Pool1 | E24: 55 | G24: MUHC | H24: BUFFY COAT | O24: Mus musculus | P24: F | Q24: GRCm39 | R24: MOUSE_3 | T24: RNASeq | U24: ILLUMINA | V24: Double stranded | W24: Illumina-Made_by_IDT_for_Illumina-Nextera_UDP_v3 | X24: UDP70008-UDP50008
A25: Library in pool | B25: DNA | C25: PooledLibrary4 | D25: Pool1 | E25: 55 | G25: MUHC | H25: BUFFY COAT | O25: Mus musculus | P25: M | Q25: GRCm39 | R25: MOUSE_4 | T25: RNASeq | U25: ILLUMINA | V25: Double stranded | W25: Illumina-Made_by_IDT_for_Illumina-Nextera_UDP_v3 | X25: UDP70009-UDP50009

Sheet UserPoolSubmission_Example
A1: Pool Submission
A2: * | C2: * | D2: * | E2: *
A3: Pool Name | B3: Pool Volume | C3: Container Kind | D3: Container Name | E3: Pool Coord | F3: Comment
A4: Pool1 | B4: 220 | C4: 96-well plate | D4: TubePool1 | E4: A01 | F4: My precious...

Sheet SampleSubmission
B1: SAMPLE SUBMISSION | E1: version 4.14.0 | F1: (*) Mandatory fields
A3: Hercules Project Name | C3: =IF(UserSampleSubmission!B3="","",UserSampleSubmission!B3)
A4: Principal Investigator | C4: =IF(UserSampleSubmission!B4="","",UserSampleSubmission!B4)
A5: Quote number | C5: =IF(UserSampleSubmission!B5="","",UserSampleSubmission!B5)
A6: Reception Date (YYYY-MM-DD) | F6: * | H6: Coordinates order | I6: =UserSampleSubmission!G6 -> Column
A8: * | B8: * | C8: * | D8: * | F8: * | H8: * | L8: * | N8: * | O8: * | T8: * | AC8: * | AD8: * | AE8: * | AG8: *
A9: Sample Type | B9: Reception (YYYY-MM-DD) | C9: Sample Kind | D9: Sample Name | E9: Alias | F9: Pool Name | G9: Ratio Library In Pool | H9: Volume (uL) | I9: Conc. (ng/uL) | J9: Collection Site | K9: Tissue Source | L9: Container Kind | M9: Container Barcode | N9: Container Name | O9: Sample Coord | P9: Location Kind | Q9: Location Barcode | R9: Location Name | S9: Container Coord | T9: Project | U9: Study | V9: Experimental Group | W9: Taxon | X9: Sex | Y9: Reference Genome | Z9: Individual Name | AA9: Individual Alias | AB9: Cohort | AC9: Library Type | AD9: Platform | AE9: Strandedness | AF9: Index Set | AG9: Index | AH9: Selection | AI9: Selection Target | AJ9: Comment
B10: =IF(SampleSubmission!A10="","",IF(SampleSubmission!C$6="","",SampleSubmission!C$6)) | C10: =IF(UserSampleSubmission!B10="","",UserSampleSubmission!B10) | D10: =IF(UserSampleSubmission!C10="","",UserSampleSubmission!C10) | F10: =IF(UserSampleSubmission!D10="","",UserSampleSubmission!D10) | G10: =IF(UserSampleSubmission!E10="","",UserSampleSubmission!E10) | H10: =IF(UserSampleSubmission!F10="","",UserSampleSubmission!F10) | I10: =IF(UserSampleSubmission!G10="","",UserSampleSubmission!G10) | J10: =IF(UserSampleSubmission!H10="","",UserSampleSubmission!H10) | K10: =IF(OR(UserSampleSubmission!A10="", UserSampleSubmission!B10="", AND(UserSampleSubmission!B10<>"DNA", UserSampleSubmission!B10<>"RNA")), "", IF(UserSampleSubmission!I10="","TISSUE",UserSampleSubmission!I10)) | L10: =IF(UserSampleSubmission!J10="","",UserSampleSubmission!J10) | M10: =IF(UserSampleSubmission!K10="","",UserSampleSubmission!K10) | N10: =IF(UserSampleSubmission!K10="","",UserSampleSubmission!K10) | O10: =IF(UserSampleSubmission!L10="","",UserSampleSubmission!L10) | P10: =IF(UserSampleSubmission!M10="","",UserSampleSubmission!M10) | Q10: =IF(R10="","",R10) | R10: =IF(UserSampleSubmission!N10="","",UserSampleSubmission!N10) | S10: =IF(UserSampleSubmission!O10="","",UserSampleSubmission!O10) | W10: =IF(UserSampleSubmission!P10="","",UserSampleSubmission!P10) | X10: =IF(UserSampleSubmission!Q10="","",UserSampleSubmission!Q10) | Y10: =IF(UserSampleSubmission!R10="","",UserSampleSubmission!R10) | Z10: =IF(UserSampleSubmission!S10="","",UserSampleSubmission!S10) | AB10: =IF(UserSampleSubmission!T10="","",UserSampleSubmission!T10) | AC10: =IF(UserSampleSubmission!U10="","",UserSampleSubmission!U10) | AD10: =IF(UserSampleSubmission!V10="","",UserSampleSubmission!V10) | AE10: =IF(UserSampleSubmission!W10="","",UserSampleSubmission!W10) | AF10: =IF(UserSampleSubmission!X10="","",UserSampleSubmission!X10) | AG10: =IF(UserSampleSubmission!Y10="","",UserSampleSubmission!Y10) | AH10: =IF(UserSampleSubmission!Z10="","",UserSampleSubmission!Z10) | AI10: =IF(UserSampleSubmission!AA10="","",UserSampleSubmission!AA10) | AJ10: =IF(UserSampleSubmission!AB10="","",UserSampleSubmission!AB10)
B11: =IF(SampleSubmission!A11="","",IF(SampleSubmission!C$6="","",SampleSubmission!C$6)) | C11: =IF(UserSampleSubmission!B11="","",UserSampleSubmission!B11) | D11: =IF(UserSampleSubmission!C11="","",UserSampleSubmission!C11) | F11: =IF(UserSampleSubmission!D11="","",UserSampleSubmission!D11) | G11: =IF(UserSampleSubmission!E11="","",UserSampleSubmission!E11) | H11: =IF(UserSampleSubmission!F11="","",UserSampleSubmission!F11) | I11: =IF(UserSampleSubmission!G11="","",UserSampleSubmission!G11) | J11: =IF(UserSampleSubmission!H11="","",UserSampleSubmission!H11) | K11: =IF(OR(UserSampleSubmission!A11="", UserSampleSubmission!B11="", AND(UserSampleSubmission!B11<>"DNA", UserSampleSubmission!B11<>"RNA")), "", IF(UserSampleSubmission!I11="","TISSUE",UserSampleSubmission!I11)) | L11: =IF(UserSampleSubmission!J11="","",UserSampleSubmission!J11) | M11: =IF(UserSampleSubmission!K11="","",UserSampleSubmission!K11) | N11: =IF(UserSampleSubmission!K11="","",UserSampleSubmission!K11) | O11: =IF(UserSampleSubmission!L11="","",UserSampleSubmission!L11) | P11: =IF(UserSampleSubmission!M11="","",UserSampleSubmission!M11) | Q11: =IF(R11="","",R11) | R11: =IF(UserSampleSubmission!N11="","",UserSampleSubmission!N11) | S11: =IF(UserSampleSubmission!O11="","",UserSampleSubmission!O11) | W11: =IF(UserSampleSubmission!P11="","",UserSampleSubmission!P11) | X11: =IF(UserSampleSubmission!Q11="","",UserSampleSubmission!Q11) | Y11: =IF(UserSampleSubmission!R11="","",UserSampleSubmission!R11) | Z11: =IF(UserSampleSubmission!S11="","",UserSampleSubmission!S11) | AB11: =IF(UserSampleSubmission!T11="","",UserSampleSubmission!T11) | AC11: =IF(UserSampleSubmission!U11="","",UserSampleSubmission!U11) | AD11: =IF(UserSampleSubmission!V11="","",UserSampleSubmission!V11) | AE11: =IF(UserSampleSubmission!W11="","",UserSampleSubmission!W11) | AF11: =IF(UserSampleSubmission!X11="","",UserSampleSubmission!X11) | AG11: =IF(UserSampleSubmission!Y11="","",UserSampleSubmission!Y11) | AH11: =IF(UserSampleSubmission!Z11="","",UserSampleSubmission!Z11) | AI11: =IF(UserSampleSubmission!AA11="","",UserSampleSubmission!AA11) | AJ11: =IF(UserSampleSubmission!AB11="","",UserSampleSubmission!AB11)
B12: =IF(SampleSubmission!A12="","",IF(SampleSubmission!C$6="","",SampleSubmission!C$6)) | C12: =IF(UserSampleSubmission!B12="","",UserSampleSubmission!B12) | D12: =IF(UserSampleSubmission!C12="","",UserSampleSubmission!C12) | F12: =IF(UserSampleSubmission!D12="","",UserSampleSubmission!D12) | G12: =IF(UserSampleSubmission!E12="","",UserSampleSubmission!E12) | H12: =IF(UserSampleSubmission!F12="","",UserSampleSubmission!F12) | I12: =IF(UserSampleSubmission!G12="","",UserSampleSubmission!G12) | J12: =IF(UserSampleSubmission!H12="","",UserSampleSubmission!H12) | K12: =IF(OR(UserSampleSubmission!A12="", UserSampleSubmission!B12="", AND(UserSampleSubmission!B12<>"DNA", UserSampleSubmission!B12<>"RNA")), "", IF(UserSampleSubmission!I12="","TISSUE",UserSampleSubmission!I12)) | L12: =IF(UserSampleSubmission!J12="","",UserSampleSubmission!J12) | M12: =IF(UserSampleSubmission!K12="","",UserSampleSubmission!K12) | N12: =IF(UserSampleSubmission!K12="","",UserSampleSubmission!K12) | O12: =IF(UserSampleSubmission!L12="","",UserSampleSubmission!L12) | P12: =IF(UserSampleSubmission!M12="","",UserSampleSubmission!M12) | Q12: =IF(R12="","",R12) | R12: =IF(UserSampleSubmission!N12="","",UserSampleSubmission!N12) | S12: =IF(UserSampleSubmission!O12="","",UserSampleSubmission!O12) | W12: =IF(UserSampleSubmission!P12="","",UserSampleSubmission!P12) | X12: =IF(UserSampleSubmission!Q12="","",UserSampleSubmission!Q12) | Y12: =IF(UserSampleSubmission!R12="","",UserSampleSubmission!R12) | Z12: =IF(UserSampleSubmission!S12="","",UserSampleSubmission!S12) | AB12: =IF(UserSampleSubmission!T12="","",UserSampleSubmission!T12) | AC12: =IF(UserSampleSubmission!U12="","",UserSampleSubmission!U12) | AD12: =IF(UserSampleSubmission!V12="","",UserSampleSubmission!V12) | AE12: =IF(UserSampleSubmission!W12="","",UserSampleSubmission!W12) | AF12: =IF(UserSampleSubmission!X12="","",UserSampleSubmission!X12) | AG12: =IF(UserSampleSubmission!Y12="","",UserSampleSubmission!Y12) | AH12: =IF(UserSampleSubmission!Z12="","",UserSampleSubmission!Z12) | AI12: =IF(UserSampleSubmission!AA12="","",UserSampleSubmission!AA12) | AJ12: =IF(UserSampleSubmission!AB12="","",UserSampleSubmission!AB12)
B13: =IF(SampleSubmission!A13="","",IF(SampleSubmission!C$6="","",SampleSubmission!C$6)) | C13: =IF(UserSampleSubmission!B13="","",UserSampleSubmission!B13) | D13: =IF(UserSampleSubmission!C13="","",UserSampleSubmission!C13) | F13: =IF(UserSampleSubmission!D13="","",UserSampleSubmission!D13) | G13: =IF(UserSampleSubmission!E13="","",UserSampleSubmission!E13) | H13: =IF(UserSampleSubmission!F13="","",UserSampleSubmission!F13) | I13: =IF(UserSampleSubmission!G13="","",UserSampleSubmission!G13) | J13: =IF(UserSampleSubmission!H13="","",UserSampleSubmission!H13) | K13: =IF(OR(UserSampleSubmission!A13="", UserSampleSubmission!B13="", AND(UserSampleSubmission!B13<>"DNA", UserSampleSubmission!B13<>"RNA")), "", IF(UserSampleSubmission!I13="","TISSUE",UserSampleSubmission!I13)) | L13: =IF(UserSampleSubmission!J13="","",UserSampleSubmission!J13) | M13: =IF(UserSampleSubmission!K13="","",UserSampleSubmission!K13) | N13: =IF(UserSampleSubmission!K13="","",UserSampleSubmission!K13) | O13: =IF(UserSampleSubmission!L13="","",UserSampleSubmission!L13) | P13: =IF(UserSampleSubmission!M13="","",UserSampleSubmission!M13) | Q13: =IF(R13="","",R13) | R13: =IF(UserSampleSubmission!N13="","",UserSampleSubmission!N13) | S13: =IF(UserSampleSubmission!O13="","",UserSampleSubmission!O13) | W13: =IF(UserSampleSubmission!P13="","",UserSampleSubmission!P13) | X13: =IF(UserSampleSubmission!Q13="","",UserSampleSubmission!Q13) | Y13: =IF(UserSampleSubmission!R13="","",UserSampleSubmission!R13) | Z13: =IF(UserSampleSubmission!S13="","",UserSampleSubmission!S13) | AB13: =IF(UserSampleSubmission!T13="","",UserSampleSubmission!T13) | AC13: =IF(UserSampleSubmission!U13="","",UserSampleSubmission!U13) | AD13: =IF(UserSampleSubmission!V13="","",UserSampleSubmission!V13) | AE13: =IF(UserSampleSubmission!W13="","",UserSampleSubmission!W13) | AF13: =IF(UserSampleSubmission!X13="","",UserSampleSubmission!X13) | AG13: =IF(UserSampleSubmission!Y13="","",UserSampleSubmission!Y13) | AH13: =IF(UserSampleSubmission!Z13="","",UserSampleSubmission!Z13) | AI13: =IF(UserSampleSubmission!AA13="","",UserSampleSubmission!AA13) | AJ13: =IF(UserSampleSubmission!AB13="","",UserSampleSubmission!AB13)
A14: =IF(UserSampleSubmission!A14="","",UserSampleSubmission!A14) | B14: =IF(SampleSubmission!A14="","",IF(SampleSubmission!C$6="","",SampleSubmission!C$6)) | C14: =IF(UserSampleSubmission!B14="","",UserSampleSubmission!B14) | D14: =IF(UserSampleSubmission!C14="","",UserSampleSubmission!C14) | F14: =IF(UserSampleSubmission!D14="","",UserSampleSubmission!D14) | G14: =IF(UserSampleSubmission!E14="","",UserSampleSubmission!E14) | H14: =IF(UserSampleSubmission!F14="","",UserSampleSubmission!F14) | I14: =IF(UserSampleSubmission!G14="","",UserSampleSubmission!G14) | J14: =IF(UserSampleSubmission!H14="","",UserSampleSubmission!H14) | K14: =IF(OR(UserSampleSubmission!A14="", UserSampleSubmission!B14="", AND(UserSampleSubmission!B14<>"DNA", UserSampleSubmission!B14<>"RNA")), "", IF(UserSampleSubmission!I14="","TISSUE",UserSampleSubmission!I14)) | L14: =IF(UserSampleSubmission!J14="","",UserSampleSubmission!J14) | M14: =IF(UserSampleSubmission!K14="","",UserSampleSubmission!K14) | N14: =IF(UserSampleSubmission!K14="","",UserSampleSubmission!K14) | O14: =IF(UserSampleSubmission!L14="","",UserSampleSubmission!L14) | P14: =IF(UserSampleSubmission!M14="","",UserSampleSubmission!M14) | Q14: =IF(R14="","",R14) | R14: =IF(UserSampleSubmission!N14="","",UserSampleSubmission!N14) | S14: =IF(UserSampleSubmission!O14="","",UserSampleSubmission!O14) | W14: =IF(UserSampleSubmission!P14="","",UserSampleSubmission!P14) | X14: =IF(UserSampleSubmission!Q14="","",UserSampleSubmission!Q14) | Y14: =IF(UserSampleSubmission!R14="","",UserSampleSubmission!R14) | Z14: =IF(UserSampleSubmission!S14="","",UserSampleSubmission!S14) | AB14: =IF(UserSampleSubmission!T14="","",UserSampleSubmission!T14) | AC14: =IF(UserSampleSubmission!U14="","",UserSampleSubmission!U14) | AD14: =IF(UserSampleSubmission!V14="","",UserSampleSubmission!V14) | AE14: =IF(UserSampleSubmission!W14="","",UserSampleSubmission!W14) | AF14: =IF(UserSampleSubmission!X14="","",UserSampleSubmission!X14) | AG14: =IF(UserSampleSubmission!Y14="","",UserSampleSubmission!Y14) | AH14: =IF(UserSampleSubmission!Z14="","",UserSampleSubmission!Z14) | AI14: =IF(UserSampleSubmission!AA14="","",UserSampleSubmission!AA14) | AJ14: =IF(UserSampleSubmission!AB14="","",UserSampleSubmission!AB14)
A15: =IF(UserSampleSubmission!A15="","",UserSampleSubmission!A15) | B15: =IF(SampleSubmission!A15="","",IF(SampleSubmission!C$6="","",SampleSubmission!C$6)) | C15: =IF(UserSampleSubmission!B15="","",UserSampleSubmission!B15) | D15: =IF(UserSampleSubmission!C15="","",UserSampleSubmission!C15) | F15: =IF(UserSampleSubmission!D15="","",UserSampleSubmission!D15) | G15: =IF(UserSampleSubmission!E15="","",UserSampleSubmission!E15) | H15: =IF(UserSampleSubmission!F15="","",UserSampleSubmission!F15) | I15: =IF(UserSampleSubmission!G15="","",UserSampleSubmission!G15) | J15: =IF(UserSampleSubmission!H15="","",UserSampleSubmission!H15) | K15: =IF(OR(UserSampleSubmission!A15="", UserSampleSubmission!B15="", AND(UserSampleSubmission!B15<>"DNA", UserSampleSubmission!B15<>"RNA")), "", IF(UserSampleSubmission!I15="","TISSUE",UserSampleSubmission!I15)) | L15: =IF(UserSampleSubmission!J15="","",UserSampleSubmission!J15) | M15: =IF(UserSampleSubmission!K15="","",UserSampleSubmission!K15) | N15: =IF(UserSampleSubmission!K15="","",UserSampleSubmission!K15) | O15: =IF(UserSampleSubmission!L15="","",UserSampleSubmission!L15) | P15: =IF(UserSampleSubmission!M15="","",UserSampleSubmission!M15) | Q15: =IF(R15="","",R15) | R15: =IF(UserSampleSubmission!N15="","",UserSampleSubmission!N15) | S15: =IF(UserSampleSubmission!O15="","",UserSampleSubmission!O15) | W15: =IF(UserSampleSubmission!P15="","",UserSampleSubmission!P15) | X15: =IF(UserSampleSubmission!Q15="","",UserSampleSubmission!Q15) | Y15: =IF(UserSampleSubmission!R15="","",UserSampleSubmission!R15) | Z15: =IF(UserSampleSubmission!S15="","",UserSampleSubmission!S15) | AB15: =IF(UserSampleSubmission!T15="","",UserSampleSubmission!T15) | AC15: =IF(UserSampleSubmission!U15="","",UserSampleSubmission!U15) | AD15: =IF(UserSampleSubmission!V15="","",UserSampleSubmission!V15) | AE15: =IF(UserSampleSubmission!W15="","",UserSampleSubmission!W15) | AF15: =IF(UserSampleSubmission!X15="","",UserSampleSubmission!X15) | AG15: =IF(UserSampleSubmission!Y15="","",UserSampleSubmission!Y15) | AH15: =IF(UserSampleSubmission!Z15="","",UserSampleSubmission!Z15) | AI15: =IF(UserSampleSubmission!AA15="","",UserSampleSubmission!AA15) | AJ15: =IF(UserSampleSubmission!AB15="","",UserSampleSubmission!AB15)
A16: =IF(UserSampleSubmission!A16="","",UserSampleSubmission!A16) | B16: =IF(SampleSubmission!A16="","",IF(SampleSubmission!C$6="","",SampleSubmission!C$6)) | C16: =IF(UserSampleSubmission!B16="","",UserSampleSubmission!B16) | D16: =IF(UserSampleSubmission!C16="","",UserSampleSubmission!C16) | F16: =IF(UserSampleSubmission!D16="","",UserSampleSubmission!D16) | G16: =IF(UserSampleSubmission!E16="","",UserSampleSubmission!E16) | H16: =IF(UserSampleSubmission!F16="","",UserSampleSubmission!F16) | I16: =IF(UserSampleSubmission!G16="","",UserSampleSubmission!G16) | J16: =IF(UserSampleSubmission!H16="","",UserSampleSubmission!H16) | K16: =IF(OR(UserSampleSubmission!A16="", UserSampleSubmission!B16="", AND(UserSampleSubmission!B16<>"DNA", UserSampleSubmission!B16<>"RNA")), "", IF(UserSampleSubmission!I16="","TISSUE",UserSampleSubmission!I16)) | L16: =IF(UserSampleSubmission!J16="","",UserSampleSubmission!J16) | M16: =IF(UserSampleSubmission!K16="","",UserSampleSubmission!K16) | N16: =IF(UserSampleSubmission!K16="","",UserSampleSubmission!K16) | O16: =IF(UserSampleSubmission!L16="","",UserSampleSubmission!L16) | P16: =IF(UserSampleSubmission!M16="","",UserSampleSubmission!M16) | Q16: =IF(R16="","",R16) | R16: =IF(UserSampleSubmission!N16="","",UserSampleSubmission!N16) | S16: =IF(UserSampleSubmission!O16="","",UserSampleSubmission!O16) | W16: =IF(UserSampleSubmission!P16="","",UserSampleSubmission!P16) | X16: =IF(UserSampleSubmission!Q16="","",UserSampleSubmission!Q16) | Y16: =IF(UserSampleSubmission!R16="","",UserSampleSubmission!R16) | Z16: =IF(UserSampleSubmission!S16="","",UserSampleSubmission!S16) | AB16: =IF(UserSampleSubmission!T16="","",UserSampleSubmission!T16) | AC16: =IF(UserSampleSubmission!U16="","",UserSampleSubmission!U16) | AD16: =IF(UserSampleSubmission!V16="","",UserSampleSubmission!V16) | AE16: =IF(UserSampleSubmission!W16="","",UserSampleSubmission!W16) | AF16: =IF(UserSampleSubmission!X16="","",UserSampleSubmission!X16) | AG16: =IF(UserSampleSubmission!Y16="","",UserSampleSubmission!Y16) | AH16: =IF(UserSampleSubmission!Z16="","",UserSampleSubmission!Z16) | AI16: =IF(UserSampleSubmission!AA16="","",UserSampleSubmission!AA16) | AJ16: =IF(UserSampleSubmission!AB16="","",UserSampleSubmission!AB16)
A17: =IF(UserSampleSubmission!A17="","",UserSampleSubmission!A17) | B17: =IF(SampleSubmission!A17="","",IF(SampleSubmission!C$6="","",SampleSubmission!C$6)) | C17: =IF(UserSampleSubmission!B17="","",UserSampleSubmission!B17) | D17: =IF(UserSampleSubmission!C17="","",UserSampleSubmission!C17) | F17: =IF(UserSampleSubmission!D17="","",UserSampleSubmission!D17) | G17: =IF(UserSampleSubmission!E17="","",UserSampleSubmission!E17) | H17: =IF(UserSampleSubmission!F17="","",UserSampleSubmission!F17) | I17: =IF(UserSampleSubmission!G17="","",UserSampleSubmission!G17) | J17: =IF(UserSampleSubmission!H17="","",UserSampleSubmission!H17) | K17: =IF(OR(UserSampleSubmission!A17="", UserSampleSubmission!B17="", AND(UserSampleSubmission!B17<>"DNA", UserSampleSubmission!B17<>"RNA")), "", IF(UserSampleSubmission!I17="","TISSUE",UserSampleSubmission!I17)) | L17: =IF(UserSampleSubmission!J17="","",UserSampleSubmission!J17) | M17: =IF(UserSampleSubmission!K17="","",UserSampleSubmission!K17) | N17: =IF(UserSampleSubmission!K17="","",UserSampleSubmission!K17) | O17: =IF(UserSampleSubmission!L17="","",UserSampleSubmission!L17) | P17: =IF(UserSampleSubmission!M17="","",UserSampleSubmission!M17) | Q17: =IF(R17="","",R17) | R17: =IF(UserSampleSubmission!N17="","",UserSampleSubmission!N17) | S17: =IF(UserSampleSubmission!O17="","",UserSampleSubmission!O17) | W17: =IF(UserSampleSubmission!P17="","",UserSampleSubmission!P17) | X17: =IF(UserSampleSubmission!Q17="","",UserSampleSubmission!Q17) | Y17: =IF(UserSampleSubmission!R17="","",UserSampleSubmission!R17) | Z17: =IF(UserSampleSubmission!S17="","",UserSampleSubmission!S17) | AB17: =IF(UserSampleSubmission!T17="","",UserSampleSubmission!T17) | AC17: =IF(UserSampleSubmission!U17="","",UserSampleSubmission!U17) | AD17: =IF(UserSampleSubmission!V17="","",UserSampleSubmission!V17) | AE17: =IF(UserSampleSubmission!W17="","",UserSampleSubmission!W17) | AF17: =IF(UserSampleSubmission!X17="","",UserSampleSubmission!X17) | AG17: =IF(UserSampleSubmission!Y17="","",UserSampleSubmission!Y17) | AH17: =IF(UserSampleSubmission!Z17="","",UserSampleSubmission!Z17) | AI17: =IF(UserSampleSubmission!AA17="","",UserSampleSubmission!AA17) | AJ17: =IF(UserSampleSubmission!AB17="","",UserSampleSubmission!AB17)
A18: =IF(UserSampleSubmission!A18="","",UserSampleSubmission!A18) | B18: =IF(SampleSubmission!A18="","",IF(SampleSubmission!C$6="","",SampleSubmission!C$6)) | C18: =IF(UserSampleSubmission!B18="","",UserSampleSubmission!B18) | D18: =IF(UserSampleSubmission!C18="","",UserSampleSubmission!C18) | F18: =IF(UserSampleSubmission!D18="","",UserSampleSubmission!D18) | G18: =IF(UserSampleSubmission!E18="","",UserSampleSubmission!E18) | H18: =IF(UserSampleSubmission!F18="","",UserSampleSubmission!F18) | I18: =IF(UserSampleSubmission!G18="","",UserSampleSubmission!G18) | J18: =IF(UserSampleSubmission!H18="","",UserSampleSubmission!H18) | K18: =IF(OR(UserSampleSubmission!A18="", UserSampleSubmission!B18="", AND(UserSampleSubmission!B18<>"DNA", UserSampleSubmission!B18<>"RNA")), "", IF(UserSampleSubmission!I18="","TISSUE",UserSampleSubmission!I18)) | L18: =IF(UserSampleSubmission!J18="","",UserSampleSubmission!J18) | M18: =IF(UserSampleSubmission!K18="","",UserSampleSubmission!K18) | N18: =IF(UserSampleSubmission!K18="","",UserSampleSubmission!K18) | O18: =IF(UserSampleSubmission!L18="","",UserSampleSubmission!L18) | P18: =IF(UserSampleSubmission!M18="","",UserSampleSubmission!M18) | Q18: =IF(R18="","",R18) | R18: =IF(UserSampleSubmission!N18="","",UserSampleSubmission!N18) | S18: =IF(UserSampleSubmission!O18="","",UserSampleSubmission!O18) | W18: =IF(UserSampleSubmission!P18="","",UserSampleSubmission!P18) | X18: =IF(UserSampleSubmission!Q18="","",UserSampleSubmission!Q18) | Y18: =IF(UserSampleSubmission!R18="","",UserSampleSubmission!R18) | Z18: =IF(UserSampleSubmission!S18="","",UserSampleSubmission!S18) | AB18: =IF(UserSampleSubmission!T18="","",UserSampleSubmission!T18) | AC18: =IF(UserSampleSubmission!U18="","",UserSampleSubmission!U18) | AD18: =IF(UserSampleSubmission!V18="","",UserSampleSubmission!V18) | AE18: =IF(UserSampleSubmission!W18="","",UserSampleSubmission!W18) | AF18: =IF(UserSampleSubmission!X18="","",UserSampleSubmission!X18) | AG18: =IF(UserSampleSubmission!Y18="","",UserSampleSubmission!Y18) | AH18: =IF(UserSampleSubmission!Z18="","",UserSampleSubmission!Z18) | AI18: =IF(UserSampleSubmission!AA18="","",UserSampleSubmission!AA18) | AJ18: =IF(UserSampleSubmission!AB18="","",UserSampleSubmission!AB18)
A19: =IF(UserSampleSubmission!A19="","",UserSampleSubmission!A19) | B19: =IF(SampleSubmission!A19="","",IF(SampleSubmission!C$6="","",SampleSubmission!C$6)) | C19: =IF(UserSampleSubmission!B19="","",UserSampleSubmission!B19) | D19: =IF(UserSampleSubmission!C19="","",UserSampleSubmission!C19) | F19: =IF(UserSampleSubmission!D19="","",UserSampleSubmission!D19) | G19: =IF(UserSampleSubmission!E19="","",UserSampleSubmission!E19) | H19: =IF(UserSampleSubmission!F19="","",UserSampleSubmission!F19) | I19: =IF(UserSampleSubmission!G19="","",UserSampleSubmission!G19) | J19: =IF(UserSampleSubmission!H19="","",UserSampleSubmission!H19) | K19: =IF(OR(UserSampleSubmission!A19="", UserSampleSubmission!B19="", AND(UserSampleSubmission!B19<>"DNA", UserSampleSubmission!B19<>"RNA")), "", IF(UserSampleSubmission!I19="","TISSUE",UserSampleSubmission!I19)) | L19: =IF(UserSampleSubmission!J19="","",UserSampleSubmission!J19) | M19: =IF(UserSampleSubmission!K19="","",UserSampleSubmission!K19) | N19: =IF(UserSampleSubmission!K19="","",UserSampleSubmission!K19) | O19: =IF(UserSampleSubmission!L19="","",UserSampleSubmission!L19) | P19: =IF(UserSampleSubmission!M19="","",UserSampleSubmission!M19) | Q19: =IF(R19="","",R19) | R19: =IF(UserSampleSubmission!N19="","",UserSampleSubmission!N19) | S19: =IF(UserSampleSubmission!O19="","",UserSampleSubmission!O19) | W19: =IF(UserSampleSubmission!P19="","",UserSampleSubmission!P19) | X19: =IF(UserSampleSubmission!Q19="","",UserSampleSubmission!Q19) | Y19: =IF(UserSampleSubmission!R19="","",UserSampleSubmission!R19) | Z19: =IF(UserSampleSubmission!S19="","",UserSampleSubmission!S19) | AB19: =IF(UserSampleSubmission!T19="","",UserSampleSubmission!T19) | AC19: =IF(UserSampleSubmission!U19="","",UserSampleSubmission!U19) | AD19: =IF(UserSampleSubmission!V19="","",UserSampleSubmission!V19) | AE19: =IF(UserSampleSubmission!W19="","",UserSampleSubmission!W19) | AF19: =IF(UserSampleSubmission!X19="","",UserSampleSubmission!X19) | AG19: =IF(UserSampleSubmission!Y19="","",UserSampleSubmission!Y19) | AH19: =IF(UserSampleSubmission!Z19="","",UserSampleSubmission!Z19) | AI19: =IF(UserSampleSubmission!AA19="","",UserSampleSubmission!AA19) | AJ19: =IF(UserSampleSubmission!AB19="","",UserSampleSubmission!AB19)
A20: =IF(UserSampleSubmission!A20="","",UserSampleSubmission!A20) | B20: =IF(SampleSubmission!A20="","",IF(SampleSubmission!C$6="","",SampleSubmission!C$6)) | C20: =IF(UserSampleSubmission!B20="","",UserSampleSubmission!B20) | D20: =IF(UserSampleSubmission!C20="","",UserSampleSubmission!C20) | F20: =IF(UserSampleSubmission!D20="","",UserSampleSubmission!D20) | G20: =IF(UserSampleSubmission!E20="","",UserSampleSubmission!E20) | H20: =IF(UserSampleSubmission!F20="","",UserSampleSubmission!F20) | I20: =IF(UserSampleSubmission!G20="","",UserSampleSubmission!G20) | J20: =IF(UserSampleSubmission!H20="","",UserSampleSubmission!H20) | K20: =IF(OR(UserSampleSubmission!A20="", UserSampleSubmission!B20="", AND(UserSampleSubmission!B20<>"DNA", UserSampleSubmission!B20<>"RNA")), "", IF(UserSampleSubmission!I20="","TISSUE",UserSampleSubmission!I20)) | L20: =IF(UserSampleSubmission!J20="","",UserSampleSubmission!J20) | M20: =IF(UserSampleSubmission!K20="","",UserSampleSubmission!K20) | N20: =IF(UserSampleSubmission!K20="","",UserSampleSubmission!K20) | O20: =IF(UserSampleSubmission!L20="","",UserSampleSubmission!L20) | P20: =IF(UserSampleSubmission!M20="","",UserSampleSubmission!M20) | Q20: =IF(R20="","",R20) | R20: =IF(UserSampleSubmission!N20="","",UserSampleSubmission!N20) | S20: =IF(UserSampleSubmission!O20="","",UserSampleSubmission!O20) | W20: =IF(UserSampleSubmission!P20="","",UserSampleSubmission!P20) | X20: =IF(UserSampleSubmission!Q20="","",UserSampleSubmission!Q20) | Y20: =IF(UserSampleSubmission!R20="","",UserSampleSubmission!R20) | Z20: =IF(UserSampleSubmission!S20="","",UserSampleSubmission!S20) | AB20: =IF(UserSampleSubmission!T20="","",UserSampleSubmission!T20) | AC20: =IF(UserSampleSubmission!U20="","",UserSampleSubmission!U20) | AD20: =IF(UserSampleSubmission!V20="","",UserSampleSubmission!V20) | AE20: =IF(UserSampleSubmission!W20="","",UserSampleSubmission!W20) | AF20: =IF(UserSampleSubmission!X20="","",UserSampleSubmission!X20) | AG20: =IF(UserSampleSubmission!Y20="","",UserSampleSubmission!Y20) | AH20: =IF(UserSampleSubmission!Z20="","",UserSampleSubmission!Z20) | AI20: =IF(UserSampleSubmission!AA20="","",UserSampleSubmission!AA20) | AJ20: =IF(UserSampleSubmission!AB20="","",UserSampleSubmission!AB20)
A21: =IF(UserSampleSubmission!A21="","",UserSampleSubmission!A21) | B21: =IF(SampleSubmission!A21="","",IF(SampleSubmission!C$6="","",SampleSubmission!C$6)) | C21: =IF(UserSampleSubmission!B21="","",UserSampleSubmission!B21) | D21: =IF(UserSampleSubmission!C21="","",UserSampleSubmission!C21) | F21: =IF(UserSampleSubmission!D21="","",UserSampleSubmission!D21) | G21: =IF(UserSampleSubmission!E21="","",UserSampleSubmission!E21) | H21: =IF(UserSampleSubmission!F21="","",UserSampleSubmission!F21) | I21: =IF(UserSampleSubmission!G21="","",UserSampleSubmission!G21) | J21: =IF(UserSampleSubmission!H21="","",UserSampleSubmission!H21) | K21: =IF(OR(UserSampleSubmission!A21="", UserSampleSubmission!B21="", AND(UserSampleSubmission!B21<>"DNA", UserSampleSubmission!B21<>"RNA")), "", IF(UserSampleSubmission!I21="","TISSUE",UserSampleSubmission!I21)) | L21: =IF(UserSampleSubmission!J21="","",UserSampleSubmission!J21) | M21: =IF(UserSampleSubmission!K21="","",UserSampleSubmission!K21) | N21: =IF(UserSampleSubmission!K21="","",UserSampleSubmission!K21) | O21: =IF(UserSampleSubmission!L21="","",UserSampleSubmission!L21) | P21: =IF(UserSampleSubmission!M21="","",UserSampleSubmission!M21) | Q21: =IF(R21="","",R21) | R21: =IF(UserSampleSubmission!N21="","",UserSampleSubmission!N21) | S21: =IF(UserSampleSubmission!O21="","",UserSampleSubmission!O21) | W21: =IF(UserSampleSubmission!P21="","",UserSampleSubmission!P21) | X21: =IF(UserSampleSubmission!Q21="","",UserSampleSubmission!Q21) | Y21: =IF(UserSampleSubmission!R21="","",UserSampleSubmission!R21) | Z21: =IF(UserSampleSubmission!S21="","",UserSampleSubmission!S21) | AB21: =IF(UserSampleSubmission!T21="","",UserSampleSubmission!T21) | AC21: =IF(UserSampleSubmission!U21="","",UserSampleSubmission!U21) | AD21: =IF(UserSampleSubmission!V21="","",UserSampleSubmission!V21) | AE21: =IF(UserSampleSubmission!W21="","",UserSampleSubmission!W21) | AF21: =IF(UserSampleSubmission!X21="","",UserSampleSubmission!X21) | AG21: =IF(UserSampleSubmission!Y21="","",UserSampleSubmission!Y21) | AH21: =IF(UserSampleSubmission!Z21="","",UserSampleSubmission!Z21) | AI21: =IF(UserSampleSubmission!AA21="","",UserSampleSubmission!AA21) | AJ21: =IF(UserSampleSubmission!AB21="","",UserSampleSubmission!AB21)
A22: =IF(UserSampleSubmission!A22="","",UserSampleSubmission!A22) | B22: =IF(SampleSubmission!A22="","",IF(SampleSubmission!C$6="","",SampleSubmission!C$6)) | C22: =IF(UserSampleSubmission!B22="","",UserSampleSubmission!B22) | D22: =IF(UserSampleSubmission!C22="","",UserSampleSubmission!C22) | F22: =IF(UserSampleSubmission!D22="","",UserSampleSubmission!D22) | G22: =IF(UserSampleSubmission!E22="","",UserSampleSubmission!E22) | H22: =IF(UserSampleSubmission!F22="","",UserSampleSubmission!F22) | I22: =IF(UserSampleSubmission!G22="","",UserSampleSubmission!G22) | J22: =IF(UserSampleSubmission!H22="","",UserSampleSubmission!H22) | K22: =IF(OR(UserSampleSubmission!A22="", UserSampleSubmission!B22="", AND(UserSampleSubmission!B22<>"DNA", UserSampleSubmission!B22<>"RNA")), "", IF(UserSampleSubmission!I22="","TISSUE",UserSampleSubmission!I22)) | L22: =IF(UserSampleSubmission!J22="","",UserSampleSubmission!J22) | M22: =IF(UserSampleSubmission!K22="","",UserSampleSubmission!K22) | N22: =IF(UserSampleSubmission!K22="","",UserSampleSubmission!K22) | O22: =IF(UserSampleSubmission!L22="","",UserSampleSubmission!L22) | P22: =IF(UserSampleSubmission!M22="","",UserSampleSubmission!M22) | Q22: =IF(R22="","",R22) | R22: =IF(UserSampleSubmission!N22="","",UserSampleSubmission!N22) | S22: =IF(UserSampleSubmission!O22="","",UserSampleSubmission!O22) | W22: =IF(UserSampleSubmission!P22="","",UserSampleSubmission!P22) | X22: =IF(UserSampleSubmission!Q22="","",UserSampleSubmission!Q22) | Y22: =IF(UserSampleSubmission!R22="","",UserSampleSubmission!R22) | Z22: =IF(UserSampleSubmission!S22="","",UserSampleSubmission!S22) | AB22: =IF(UserSampleSubmission!T22="","",UserSampleSubmission!T22) | AC22: =IF(UserSampleSubmission!U22="","",UserSampleSubmission!U22) | AD22: =IF(UserSampleSubmission!V22="","",UserSampleSubmission!V22) | AE22: =IF(UserSampleSubmission!W22="","",UserSampleSubmission!W22) | AF22: =IF(UserSampleSubmission!X22="","",UserSampleSubmission!X22) | AG22: =IF(UserSampleSubmission!Y22="","",UserSampleSubmission!Y22) | AH22: =IF(UserSampleSubmission!Z22="","",UserSampleSubmission!Z22) | AI22: =IF(UserSampleSubmission!AA22="","",UserSampleSubmission!AA22) | AJ22: =IF(UserSampleSubmission!AB22="","",UserSampleSubmission!AB22)
A23: =IF(UserSampleSubmission!A23="","",UserSampleSubmission!A23) | B23: =IF(SampleSubmission!A23="","",IF(SampleSubmission!C$6="","",SampleSubmission!C$6)) | C23: =IF(UserSampleSubmission!B23="","",UserSampleSubmission!B23) | D23: =IF(UserSampleSubmission!C23="","",UserSampleSubmission!C23) | F23: =IF(UserSampleSubmission!D23="","",UserSampleSubmission!D23) | G23: =IF(UserSampleSubmission!E23="","",UserSampleSubmission!E23) | H23: =IF(UserSampleSubmission!F23="","",UserSampleSubmission!F23) | I23: =IF(UserSampleSubmission!G23="","",UserSampleSubmission!G23) | J23: =IF(UserSampleSubmission!H23="","",UserSampleSubmission!H23) | K23: =IF(OR(UserSampleSubmission!A23="", UserSampleSubmission!B23="", AND(UserSampleSubmission!B23<>"DNA", UserSampleSubmission!B23<>"RNA")), "", IF(UserSampleSubmission!I23="","TISSUE",UserSampleSubmission!I23)) | L23: =IF(UserSampleSubmission!J23="","",UserSampleSubmission!J23) | M23: =IF(UserSampleSubmission!K23="","",UserSampleSubmission!K23) | N23: =IF(UserSampleSubmission!K23="","",UserSampleSubmission!K23) | O23: =IF(UserSampleSubmission!L23="","",UserSampleSubmission!L23) | P23: =IF(UserSampleSubmission!M23="","",UserSampleSubmission!M23) | Q23: =IF(R23="","",R23) | R23: =IF(UserSampleSubmission!N23="","",UserSampleSubmission!N23) | S23: =IF(UserSampleSubmission!O23="","",UserSampleSubmission!O23) | W23: =IF(UserSampleSubmission!P23="","",UserSampleSubmission!P23) | X23: =IF(UserSampleSubmission!Q23="","",UserSampleSubmission!Q23) | Y23: =IF(UserSampleSubmission!R23="","",UserSampleSubmission!R23) | Z23: =IF(UserSampleSubmission!S23="","",UserSampleSubmission!S23) | AB23: =IF(UserSampleSubmission!T23="","",UserSampleSubmission!T23) | AC23: =IF(UserSampleSubmission!U23="","",UserSampleSubmission!U23) | AD23: =IF(UserSampleSubmission!V23="","",UserSampleSubmission!V23) | AE23: =IF(UserSampleSubmission!W23="","",UserSampleSubmission!W23) | AF23: =IF(UserSampleSubmission!X23="","",UserSampleSubmission!X23) | AG23: =IF(UserSampleSubmission!Y23="","",UserSampleSubmission!Y23) | AH23: =IF(UserSampleSubmission!Z23="","",UserSampleSubmission!Z23) | AI23: =IF(UserSampleSubmission!AA23="","",UserSampleSubmission!AA23) | AJ23: =IF(UserSampleSubmission!AB23="","",UserSampleSubmission!AB23)
A24: =IF(UserSampleSubmission!A24="","",UserSampleSubmission!A24) | B24: =IF(SampleSubmission!A24="","",IF(SampleSubmission!C$6="","",SampleSubmission!C$6)) | C24: =IF(UserSampleSubmission!B24="","",UserSampleSubmission!B24) | D24: =IF(UserSampleSubmission!C24="","",UserSampleSubmission!C24) | F24: =IF(UserSampleSubmission!D24="","",UserSampleSubmission!D24) | G24: =IF(UserSampleSubmission!E24="","",UserSampleSubmission!E24) | H24: =IF(UserSampleSubmission!F24="","",UserSampleSubmission!F24) | I24: =IF(UserSampleSubmission!G24="","",UserSampleSubmission!G24) | J24: =IF(UserSampleSubmission!H24="","",UserSampleSubmission!H24) | K24: =IF(OR(UserSampleSubmission!A24="", UserSampleSubmission!B24="", AND(UserSampleSubmission!B24<>"DNA", UserSampleSubmission!B24<>"RNA")), "", IF(UserSampleSubmission!I24="","TISSUE",UserSampleSubmission!I24)) | L24: =IF(UserSampleSubmission!J24="","",UserSampleSubmission!J24) | M24: =IF(UserSampleSubmission!K24="","",UserSampleSubmission!K24) | N24: =IF(UserSampleSubmission!K24="","",UserSampleSubmission!K24) | O24: =IF(UserSampleSubmission!L24="","",UserSampleSubmission!L24) | P24: =IF(UserSampleSubmission!M24="","",UserSampleSubmission!M24) | Q24: =IF(R24="","",R24) | R24: =IF(UserSampleSubmission!N24="","",UserSampleSubmission!N24) | S24: =IF(UserSampleSubmission!O24="","",UserSampleSubmission!O24) | W24: =IF(UserSampleSubmission!P24="","",UserSampleSubmission!P24) | X24: =IF(UserSampleSubmission!Q24="","",UserSampleSubmission!Q24) | Y24: =IF(UserSampleSubmission!R24="","",UserSampleSubmission!R24) | Z24: =IF(UserSampleSubmission!S24="","",UserSampleSubmission!S24) | AB24: =IF(UserSampleSubmission!T24="","",UserSampleSubmission!T24) | AC24: =IF(UserSampleSubmission!U24="","",UserSampleSubmission!U24) | AD24: =IF(UserSampleSubmission!V24="","",UserSampleSubmission!V24) | AE24: =IF(UserSampleSubmission!W24="","",UserSampleSubmission!W24) | AF24: =IF(UserSampleSubmission!X24="","",UserSampleSubmission!X24) | AG24: =IF(UserSampleSubmission!Y24="","",UserSampleSubmission!Y24) | AH24: =IF(UserSampleSubmission!Z24="","",UserSampleSubmission!Z24) | AI24: =IF(UserSampleSubmission!AA24="","",UserSampleSubmission!AA24) | AJ24: =IF(UserSampleSubmission!AB24="","",UserSampleSubmission!AB24)
A25: =IF(UserSampleSubmission!A25="","",UserSampleSubmission!A25) | B25: =IF(SampleSubmission!A25="","",IF(SampleSubmission!C$6="","",SampleSubmission!C$6)) | C25: =IF(UserSampleSubmission!B25="","",UserSampleSubmission!B25) | D25: =IF(UserSampleSubmission!C25="","",UserSampleSubmission!C25) | F25: =IF(UserSampleSubmission!D25="","",UserSampleSubmission!D25) | G25: =IF(UserSampleSubmission!E25="","",UserSampleSubmission!E25) | H25: =IF(UserSampleSubmission!F25="","",UserSampleSubmission!F25) | I25: =IF(UserSampleSubmission!G25="","",UserSampleSubmission!G25) | J25: =IF(UserSampleSubmission!H25="","",UserSampleSubmission!H25) | K25: =IF(OR(UserSampleSubmission!A25="", UserSampleSubmission!B25="", AND(UserSampleSubmission!B25<>"DNA", UserSampleSubmission!B25<>"RNA")), "", IF(UserSampleSubmission!I25="","TISSUE",UserSampleSubmission!I25)) | L25: =IF(UserSampleSubmission!J25="","",UserSampleSubmission!J25) | M25: =IF(UserSampleSubmission!K25="","",UserSampleSubmission!K25) | N25: =IF(UserSampleSubmission!K25="","",UserSampleSubmission!K25) | O25: =IF(UserSampleSubmission!L25="","",UserSampleSubmission!L25) | P25: =IF(UserSampleSubmission!M25="","",UserSampleSubmission!M25) | Q25: =IF(R25="","",R25) | R25: =IF(UserSampleSubmission!N25="","",UserSampleSubmission!N25) | S25: =IF(UserSampleSubmission!O25="","",UserSampleSubmission!O25) | W25: =IF(UserSampleSubmission!P25="","",UserSampleSubmission!P25) | X25: =IF(UserSampleSubmission!Q25="","",UserSampleSubmission!Q25) | Y25: =IF(UserSampleSubmission!R25="","",UserSampleSubmission!R25) | Z25: =IF(UserSampleSubmission!S25="","",UserSampleSubmission!S25) | AB25: =IF(UserSampleSubmission!T25="","",UserSampleSubmission!T25) | AC25: =IF(UserSampleSubmission!U25="","",UserSampleSubmission!U25) | AD25: =IF(UserSampleSubmission!V25="","",UserSampleSubmission!V25) | AE25: =IF(UserSampleSubmission!W25="","",UserSampleSubmission!W25) | AF25: =IF(UserSampleSubmission!X25="","",UserSampleSubmission!X25) | AG25: =IF(UserSampleSubmission!Y25="","",UserSampleSubmission!Y25) | AH25: =IF(UserSampleSubmission!Z25="","",UserSampleSubmission!Z25) | AI25: =IF(UserSampleSubmission!AA25="","",UserSampleSubmission!AA25) | AJ25: =IF(UserSampleSubmission!AB25="","",UserSampleSubmission!AB25)
... A30: =IF(UserSampleSubmission!A30="","",UserSampleSubmission!A30) | B30: =IF(SampleSubmission!A30="","",IF(SampleSubmission!C$6="","",SampleSubmission!C$6)) | C30: =IF(UserSampleSubmission!B30="","",UserSampleSubmission!B30) | D30: =IF(UserSampleSubmission!C30="","",UserSampleSubmission!C30) | F30: =IF(UserSampleSubmission!D30="","",UserSampleSubmission!D30) | G30: =IF(UserSampleSubmission!E30="","",UserSampleSubmission!E30) | H30: =IF(UserSampleSubmission!F30="","",UserSampleSubmission!F30) | I30: =IF(UserSampleSubmission!G30="","",UserSampleSubmission!G30) | J30: =IF(UserSampleSubmission!H30="","",UserSampleSubmission!H30) | K30: =IF(OR(UserSampleSubmission!A30="", UserSampleSubmission!B30="", AND(UserSampleSubmission!B30<>"DNA", UserSampleSubmission!B30<>"RNA")), "", IF(UserSampleSubmission!I30="","TISSUE",UserSampleSubmission!I30)) | L30: =IF(UserSampleSubmission!J30="","",UserSampleSubmission!J30) | M30: =IF(UserSampleSubmission!K30="","",UserSampleSubmission!K30) | N30: =IF(UserSampleSubmission!K30="","",UserSampleSubmission!K30) | O30: =IF(UserSampleSubmission!L30="","",UserSampleSubmission!L30) | P30: =IF(UserSampleSubmission!M30="","",UserSampleSubmission!M30) | Q30: =IF(R30="","",R30) | R30: =IF(UserSampleSubmission!N30="","",UserSampleSubmission!N30) | S30: =IF(UserSampleSubmission!O30="","",UserSampleSubmission!O30) | W30: =IF(UserSampleSubmission!P30="","",UserSampleSubmission!P30) | X30: =IF(UserSampleSubmission!Q30="","",UserSampleSubmission!Q30) | Y30: =IF(UserSampleSubmission!R30="","",UserSampleSubmission!R30) | Z30: =IF(UserSampleSubmission!S30="","",UserSampleSubmission!S30) | AB30: =IF(UserSampleSubmission!T30="","",UserSampleSubmission!T30) | AC30: =IF(UserSampleSubmission!U30="","",UserSampleSubmission!U30) | AD30: =IF(UserSampleSubmission!V30="","",UserSampleSubmission!V30) | AE30: =IF(UserSampleSubmission!W30="","",UserSampleSubmission!W30) | AF30: =IF(UserSampleSubmission!X30="","",UserSampleSubmission!X30) | AG30: =IF(UserSampleSubmission!Y30="","",UserSampleSubmission!Y30) | AH30: =IF(UserSampleSubmission!Z30="","",UserSampleSubmission!Z30) | AI30: =IF(UserSampleSubmission!AA30="","",UserSampleSubmission!AA30) | AJ30: =IF(UserSampleSubmission!AB30="","",UserSampleSubmission!AB30)
A31: =IF(UserSampleSubmission!A31="","",UserSampleSubmission!A31) | B31: =IF(SampleSubmission!A31="","",IF(SampleSubmission!C$6="","",SampleSubmission!C$6)) | C31: =IF(UserSampleSubmission!B31="","",UserSampleSubmission!B31) | D31: =IF(UserSampleSubmission!C31="","",UserSampleSubmission!C31) | F31: =IF(UserSampleSubmission!D31="","",UserSampleSubmission!D31) | G31: =IF(UserSampleSubmission!E31="","",UserSampleSubmission!E31) | H31: =IF(UserSampleSubmission!F31="","",UserSampleSubmission!F31) | I31: =IF(UserSampleSubmission!G31="","",UserSampleSubmission!G31) | J31: =IF(UserSampleSubmission!H31="","",UserSampleSubmission!H31) | K31: =IF(OR(UserSampleSubmission!A31="", UserSampleSubmission!B31="", AND(UserSampleSubmission!B31<>"DNA", UserSampleSubmission!B31<>"RNA")), "", IF(UserSampleSubmission!I31="","TISSUE",UserSampleSubmission!I31)) | L31: =IF(UserSampleSubmission!J31="","",UserSampleSubmission!J31) | M31: =IF(UserSampleSubmission!K31="","",UserSampleSubmission!K31) | N31: =IF(UserSampleSubmission!K31="","",UserSampleSubmission!K31) | O31: =IF(UserSampleSubmission!L31="","",UserSampleSubmission!L31) | Q31: =IF(R31="","",R31) | R31: =IF(UserSampleSubmission!N31="","",UserSampleSubmission!N31) | S31: =IF(UserSampleSubmission!O31="","",UserSampleSubmission!O31) | W31: =IF(UserSampleSubmission!P31="","",UserSampleSubmission!P31) | X31: =IF(UserSampleSubmission!Q31="","",UserSampleSubmission!Q31) | Y31: =IF(UserSampleSubmission!R31="","",UserSampleSubmission!R31) | Z31: =IF(UserSampleSubmission!S31="","",UserSampleSubmission!S31) | AB31: =IF(UserSampleSubmission!T31="","",UserSampleSubmission!T31) | AC31: =IF(UserSampleSubmission!U31="","",UserSampleSubmission!U31) | AD31: =IF(UserSampleSubmission!V31="","",UserSampleSubmission!V31) | AE31: =IF(UserSampleSubmission!W31="","",UserSampleSubmission!W31) | AF31: =IF(UserSampleSubmission!X31="","",UserSampleSubmission!X31) | AG31: =IF(UserSampleSubmission!Y31="","",UserSampleSubmission!Y31) | AH31: =IF(UserSampleSubmission!Z31="","",UserSampleSubmission!Z31) | AI31: =IF(UserSampleSubmission!AA31="","",UserSampleSubmission!AA31) | AJ31: =IF(UserSampleSubmission!AB31="","",UserSampleSubmission!AB31)
A32: =IF(UserSampleSubmission!A32="","",UserSampleSubmission!A32) | B32: =IF(SampleSubmission!A32="","",IF(SampleSubmission!C$6="","",SampleSubmission!C$6)) | C32: =IF(UserSampleSubmission!B32="","",UserSampleSubmission!B32) | D32: =IF(UserSampleSubmission!C32="","",UserSampleSubmission!C32) | F32: =IF(UserSampleSubmission!D32="","",UserSampleSubmission!D32) | G32: =IF(UserSampleSubmission!E32="","",UserSampleSubmission!E32) | H32: =IF(UserSampleSubmission!F32="","",UserSampleSubmission!F32) | I32: =IF(UserSampleSubmission!G32="","",UserSampleSubmission!G32) | J32: =IF(UserSampleSubmission!H32="","",UserSampleSubmission!H32) | K32: =IF(OR(UserSampleSubmission!A32="", UserSampleSubmission!B32="", AND(UserSampleSubmission!B32<>"DNA", UserSampleSubmission!B32<>"RNA")), "", IF(UserSampleSubmission!I32="","TISSUE",UserSampleSubmission!I32)) | L32: =IF(UserSampleSubmission!J32="","",UserSampleSubmission!J32) | M32: =IF(UserSampleSubmission!K32="","",UserSampleSubmission!K32) | N32: =IF(UserSampleSubmission!K32="","",UserSampleSubmission!K32) | O32: =IF(UserSampleSubmission!L32="","",UserSampleSubmission!L32) | P32: =IF(UserSampleSubmission!M32="","",UserSampleSubmission!M32) | Q32: =IF(R32="","",R32) | R32: =IF(UserSampleSubmission!N32="","",UserSampleSubmission!N32) | S32: =IF(UserSampleSubmission!O32="","",UserSampleSubmission!O32) | W32: =IF(UserSampleSubmission!P32="","",UserSampleSubmission!P32) | X32: =IF(UserSampleSubmission!Q32="","",UserSampleSubmission!Q32) | Y32: =IF(UserSampleSubmission!R32="","",UserSampleSubmission!R32) | Z32: =IF(UserSampleSubmission!S32="","",UserSampleSubmission!S32) | AB32: =IF(UserSampleSubmission!T32="","",UserSampleSubmission!T32) | AC32: =IF(UserSampleSubmission!U32="","",UserSampleSubmission!U32) | AD32: =IF(UserSampleSubmission!V32="","",UserSampleSubmission!V32) | AE32: =IF(UserSampleSubmission!W32="","",UserSampleSubmission!W32) | AF32: =IF(UserSampleSubmission!X32="","",UserSampleSubmission!X32) | AG32: =IF(UserSampleSubmission!Y32="","",UserSampleSubmission!Y32) | AH32: =IF(UserSampleSubmission!Z32="","",UserSampleSubmission!Z32) | AI32: =IF(UserSampleSubmission!AA32="","",UserSampleSubmission!AA32) | AJ32: =IF(UserSampleSubmission!AB32="","",UserSampleSubmission!AB32)
A33: =IF(UserSampleSubmission!A33="","",UserSampleSubmission!A33) | B33: =IF(SampleSubmission!A33="","",IF(SampleSubmission!C$6="","",SampleSubmission!C$6)) | C33: =IF(UserSampleSubmission!B33="","",UserSampleSubmission!B33) | D33: =IF(UserSampleSubmission!C33="","",UserSampleSubmission!C33) | F33: =IF(UserSampleSubmission!D33="","",UserSampleSubmission!D33) | G33: =IF(UserSampleSubmission!E33="","",UserSampleSubmission!E33) | H33: =IF(UserSampleSubmission!F33="","",UserSampleSubmission!F33) | I33: =IF(UserSampleSubmission!G33="","",UserSampleSubmission!G33) | J33: =IF(UserSampleSubmission!H33="","",UserSampleSubmission!H33) | K33: =IF(OR(UserSampleSubmission!A33="", UserSampleSubmission!B33="", AND(UserSampleSubmission!B33<>"DNA", UserSampleSubmission!B33<>"RNA")), "", IF(UserSampleSubmission!I33="","TISSUE",UserSampleSubmission!I33)) | L33: =IF(UserSampleSubmission!J33="","",UserSampleSubmission!J33) | M33: =IF(UserSampleSubmission!K33="","",UserSampleSubmission!K33) | N33: =IF(UserSampleSubmission!K33="","",UserSampleSubmission!K33) | O33: =IF(UserSampleSubmission!L33="","",UserSampleSubmission!L33) | P33: =IF(UserSampleSubmission!M33="","",UserSampleSubmission!M33) | Q33: =IF(R33="","",R33) | R33: =IF(UserSampleSubmission!N33="","",UserSampleSubmission!N33) | S33: =IF(UserSampleSubmission!O33="","",UserSampleSubmission!O33) | W33: =IF(UserSampleSubmission!P33="","",UserSampleSubmission!P33) | X33: =IF(UserSampleSubmission!Q33="","",UserSampleSubmission!Q33) | Y33: =IF(UserSampleSubmission!R33="","",UserSampleSubmission!R33) | Z33: =IF(UserSampleSubmission!S33="","",UserSampleSubmission!S33) | AB33: =IF(UserSampleSubmission!T33="","",UserSampleSubmission!T33) | AC33: =IF(UserSampleSubmission!U33="","",UserSampleSubmission!U33) | AD33: =IF(UserSampleSubmission!V33="","",UserSampleSubmission!V33) | AE33: =IF(UserSampleSubmission!W33="","",UserSampleSubmission!W33) | AF33: =IF(UserSampleSubmission!X33="","",UserSampleSubmission!X33) | AG33: =IF(UserSampleSubmission!Y33="","",UserSampleSubmission!Y33) | AH33: =IF(UserSampleSubmission!Z33="","",UserSampleSubmission!Z33) | AI33: =IF(UserSampleSubmission!AA33="","",UserSampleSubmission!AA33) | AJ33: =IF(UserSampleSubmission!AB33="","",UserSampleSubmission!AB33)
A34: =IF(UserSampleSubmission!A34="","",UserSampleSubmission!A34) | B34: =IF(SampleSubmission!A34="","",IF(SampleSubmission!C$6="","",SampleSubmission!C$6)) | C34: =IF(UserSampleSubmission!B34="","",UserSampleSubmission!B34) | D34: =IF(UserSampleSubmission!C34="","",UserSampleSubmission!C34) | F34: =IF(UserSampleSubmission!D34="","",UserSampleSubmission!D34) | G34: =IF(UserSampleSubmission!E34="","",UserSampleSubmission!E34) | H34: =IF(UserSampleSubmission!F34="","",UserSampleSubmission!F34) | I34: =IF(UserSampleSubmission!G34="","",UserSampleSubmission!G34) | J34: =IF(UserSampleSubmission!H34="","",UserSampleSubmission!H34) | K34: =IF(OR(UserSampleSubmission!A34="", UserSampleSubmission!B34="", AND(UserSampleSubmission!B34<>"DNA", UserSampleSubmission!B34<>"RNA")), "", IF(UserSampleSubmission!I34="","TISSUE",UserSampleSubmission!I34)) | L34: =IF(UserSampleSubmission!J34="","",UserSampleSubmission!J34) | M34: =IF(UserSampleSubmission!K34="","",UserSampleSubmission!K34) | N34: =IF(UserSampleSubmission!K34="","",UserSampleSubmission!K34) | O34: =IF(UserSampleSubmission!L34="","",UserSampleSubmission!L34) | P34: =IF(UserSampleSubmission!M34="","",UserSampleSubmission!M34) | Q34: =IF(R34="","",R34) | R34: =IF(UserSampleSubmission!N34="","",UserSampleSubmission!N34) | S34: =IF(UserSampleSubmission!O34="","",UserSampleSubmission!O34) | W34: =IF(UserSampleSubmission!P34="","",UserSampleSubmission!P34) | X34: =IF(UserSampleSubmission!Q34="","",UserSampleSubmission!Q34) | Y34: =IF(UserSampleSubmission!R34="","",UserSampleSubmission!R34) | Z34: =IF(UserSampleSubmission!S34="","",UserSampleSubmission!S34) | AB34: =IF(UserSampleSubmission!T34="","",UserSampleSubmission!T34) | AC34: =IF(UserSampleSubmission!U34="","",UserSampleSubmission!U34) | AD34: =IF(UserSampleSubmission!V34="","",UserSampleSubmission!V34) | AE34: =IF(UserSampleSubmission!W34="","",UserSampleSubmission!W34) | AF34: =IF(UserSampleSubmission!X34="","",UserSampleSubmission!X34) | AG34: =IF(UserSampleSubmission!Y34="","",UserSampleSubmission!Y34) | AH34: =IF(UserSampleSubmission!Z34="","",UserSampleSubmission!Z34) | AI34: =IF(UserSampleSubmission!AA34="","",UserSampleSubmission!AA34) | AJ34: =IF(UserSampleSubmission!AB34="","",UserSampleSubmission!AB34)
A35: =IF(UserSampleSubmission!A35="","",UserSampleSubmission!A35) | B35: =IF(SampleSubmission!A35="","",IF(SampleSubmission!C$6="","",SampleSubmission!C$6)) | C35: =IF(UserSampleSubmission!B35="","",UserSampleSubmission!B35) | D35: =IF(UserSampleSubmission!C35="","",UserSampleSubmission!C35) | F35: =IF(UserSampleSubmission!D35="","",UserSampleSubmission!D35) | G35: =IF(UserSampleSubmission!E35="","",UserSampleSubmission!E35) | H35: =IF(UserSampleSubmission!F35="","",UserSampleSubmission!F35) | I35: =IF(UserSampleSubmission!G35="","",UserSampleSubmission!G35) | J35: =IF(UserSampleSubmission!H35="","",UserSampleSubmission!H35) | K35: =IF(OR(UserSampleSubmission!A35="", UserSampleSubmission!B35="", AND(UserSampleSubmission!B35<>"DNA", UserSampleSubmission!B35<>"RNA")), "", IF(UserSampleSubmission!I35="","TISSUE",UserSampleSubmission!I35)) | L35: =IF(UserSampleSubmission!J35="","",UserSampleSubmission!J35) | M35: =IF(UserSampleSubmission!K35="","",UserSampleSubmission!K35) | N35: =IF(UserSampleSubmission!K35="","",UserSampleSubmission!K35) | O35: =IF(UserSampleSubmission!L35="","",UserSampleSubmission!L35) | P35: =IF(UserSampleSubmission!M35="","",UserSampleSubmission!M35) | Q35: =IF(R35="","",R35) | R35: =IF(UserSampleSubmission!N35="","",UserSampleSubmission!N35) | S35: =IF(UserSampleSubmission!O35="","",UserSampleSubmission!O35) | W35: =IF(UserSampleSubmission!P35="","",UserSampleSubmission!P35) | X35: =IF(UserSampleSubmission!Q35="","",UserSampleSubmission!Q35) | Y35: =IF(UserSampleSubmission!R35="","",UserSampleSubmission!R35) | Z35: =IF(UserSampleSubmission!S35="","",UserSampleSubmission!S35) | AB35: =IF(UserSampleSubmission!T35="","",UserSampleSubmission!T35) | AC35: =IF(UserSampleSubmission!U35="","",UserSampleSubmission!U35) | AD35: =IF(UserSampleSubmission!V35="","",UserSampleSubmission!V35) | AE35: =IF(UserSampleSubmission!W35="","",UserSampleSubmission!W35) | AF35: =IF(UserSampleSubmission!X35="","",UserSampleSubmission!X35) | AG35: =IF(UserSampleSubmission!Y35="","",UserSampleSubmission!Y35) | AH35: =IF(UserSampleSubmission!Z35="","",UserSampleSubmission!Z35) | AI35: =IF(UserSampleSubmission!AA35="","",UserSampleSubmission!AA35) | AJ35: =IF(UserSampleSubmission!AB35="","",UserSampleSubmission!AB35)
A36: =IF(UserSampleSubmission!A36="","",UserSampleSubmission!A36) | B36: =IF(SampleSubmission!A36="","",IF(SampleSubmission!C$6="","",SampleSubmission!C$6)) | C36: =IF(UserSampleSubmission!B36="","",UserSampleSubmission!B36) | D36: =IF(UserSampleSubmission!C36="","",UserSampleSubmission!C36) | F36: =IF(UserSampleSubmission!D36="","",UserSampleSubmission!D36) | G36: =IF(UserSampleSubmission!E36="","",UserSampleSubmission!E36) | H36: =IF(UserSampleSubmission!F36="","",UserSampleSubmission!F36) | I36: =IF(UserSampleSubmission!G36="","",UserSampleSubmission!G36) | J36: =IF(UserSampleSubmission!H36="","",UserSampleSubmission!H36) | K36: =IF(OR(UserSampleSubmission!A36="", UserSampleSubmission!B36="", AND(UserSampleSubmission!B36<>"DNA", UserSampleSubmission!B36<>"RNA")), "", IF(UserSampleSubmission!I36="","TISSUE",UserSampleSubmission!I36)) | L36: =IF(UserSampleSubmission!J36="","",UserSampleSubmission!J36) | M36: =IF(UserSampleSubmission!K36="","",UserSampleSubmission!K36) | N36: =IF(UserSampleSubmission!K36="","",UserSampleSubmission!K36) | O36: =IF(UserSampleSubmission!L36="","",UserSampleSubmission!L36) | P36: =IF(UserSampleSubmission!M36="","",UserSampleSubmission!M36) | Q36: =IF(R36="","",R36) | R36: =IF(UserSampleSubmission!N36="","",UserSampleSubmission!N36) | S36: =IF(UserSampleSubmission!O36="","",UserSampleSubmission!O36) | W36: =IF(UserSampleSubmission!P36="","",UserSampleSubmission!P36) | X36: =IF(UserSampleSubmission!Q36="","",UserSampleSubmission!Q36) | Y36: =IF(UserSampleSubmission!R36="","",UserSampleSubmission!R36) | Z36: =IF(UserSampleSubmission!S36="","",UserSampleSubmission!S36) | AB36: =IF(UserSampleSubmission!T36="","",UserSampleSubmission!T36) | AC36: =IF(UserSampleSubmission!U36="","",UserSampleSubmission!U36) | AD36: =IF(UserSampleSubmission!V36="","",UserSampleSubmission!V36) | AE36: =IF(UserSampleSubmission!W36="","",UserSampleSubmission!W36) | AF36: =IF(UserSampleSubmission!X36="","",UserSampleSubmission!X36) | AG36: =IF(UserSampleSubmission!Y36="","",UserSampleSubmission!Y36) | AH36: =IF(UserSampleSubmission!Z36="","",UserSampleSubmission!Z36) | AI36: =IF(UserSampleSubmission!AA36="","",UserSampleSubmission!AA36) | AJ36: =IF(UserSampleSubmission!AB36="","",UserSampleSubmission!AB36)
